Workbook

Sheet Dashboard
A1: Max Garcia — Forward Card Calendar
A2: April 2026 → March 2029 (35 months). Buy signals, windows, and priority tiers synthesized from publisher releases and established cadences.
A4: Patience pays. 🦞
A6: At-a-glance counts
A7: Total events tracked | B7: =COUNTA(Master_Calendar!B5:B200)-1 -> 74
A8: Priority 1 (must buy) | B8: =COUNTIF(Master_Calendar!L5:L200,"1 — Must buy") -> 21
A9: Priority 2 (strong buy) | B9: =COUNTIF(Master_Calendar!L5:L200,"2 — Strong buy") -> 18
A10: Priority 5 (AVOID) | B10: =COUNTIF(Master_Calendar!L5:L200,"5 — Avoid") -> 1
A11: Total budget allocated across calendar | B11: =SUM(Master_Calendar!M5:M200) -> 5422
A14: Which sheet do I open?
A15: Sheet | B15: Use it when
A16: This_Month | B16: What should I buy THIS MONTH? Formula-driven live view.
A17: Master_Calendar | B17: Every event chronologically. Filter by date or category.
A18: Pokemon / Magic / etc. | B18: Category deep dives with all events pre-filtered.
A19: Catalysts | B19: Anniversaries, tournaments, films — non-purchase events that move prices.
A20: Scalper_Watchlist | B20: SKUs to grab at MSRP the moment they drop.
A21: Reprint_Risk | B21: Products/cards to AVOID because reprints are imminent.
A22: Buy_Queue | B22: Priority-ranked action list with budget allocation summed.
A25: Action-signal key
A26: Signal | B26: What it means
A27: Preorder now | B27: Lock in MSRP before release — product will be scarce on drop day.
A28: Buy at MSRP on release | B28: Buy at retail MSRP on release day; will not get cheaper.
A29: Wait 90 days for trough | B29: Wait ~3 months for post-release trough. Typically 15-25% below MSRP.
A30: Wait 6 months for clearance | B30: Wait ~6 months for clearance pricing or inventory dump.
A31: Wait 12 months for stability | B31: Wait 12 months for price stability before buying.
A32: Accumulate steadily | B32: Buy small positions steadily over the entire window.
A33: Monitor only | B33: Not a purchase — watch conditions for information or later action.
A34: SKIP — do not buy | B34: Do not buy at any point. Worst expected value in the category.

Sheet Mid_2026_Refresh
A1: Forward Calendar — Mid-2026 Refresh Notes
A2: Market refresh as of June 14, 2026. Read before acting on older rows.
A4: Patience pays. 🦞
A6: # | B6: Mid-2026 update
A7: 1 | B7: POKEMON 30th CELEBRATION: Sept 16-18, 2026 — first-ever worldwide simultaneous Pokemon release. All-foil packs, new opalescent Futuristic Rare, Base Charizard reprint, 30 Pikachu by YOSHIROTTEN, plus a Premium Deck Set (Espeon/Umbreon). Treat as a buy-everything event; expect retail to evaporate.
A8: 2 | B8: POKEMON Mega-era 2026 cadence: Ascended Heroes (Jan 30), Phantasmal Flames / Mega Charizard X (Mar 13), Perfect Order (Mar 27), Chaos Rising (May 22, PRIORITY preorder), Pitch Black / Mega Darkrai (Jul 17, PRIORITY MSRP day-of), Storm Emerald / Mega Rayquaza (~Sept, confirm date).
A9: 3 | B9: ONE PIECE: simultaneous global releases began with OP-15 (Apr 3). OP-16 Paramount War is the current set (Jun 12, $120/box). OP-17 4th-anniversary set ~August. WATCH: an August 2026 Premium Bandai restock of OP-13 could pull its ~$725 price down.
A10: 4 | B10: MTG 2026: TMNT (Mar 6), Secrets of Strixhaven (Apr 24), Edge of Eternities (Apr 24), Marvel Super Heroes (Jun 26), The Hobbit (Aug), Reality Fracture (Oct 2), Star Trek (~Nov 20). Standard rotation rules change in 2027.
A11: 5 | B11: LORCANA 2026: Winterspell (Feb 13), Wilds Unknown / first Pixar crossover (May 15, new Iconic rarity), Attack of the Vine! / Monsters Inc. (Jul 24), a Coco-themed Q4 set, and Illumineer’s Quest: Great Hunny Rescue (Oct, $59.99).
A12: 6 | B12: GRADING: PSA Value-tier freeze (Jun 2) and ~14M backlog mean grading turnaround is a live calendar constraint through roughly Nov 2026. Plan submissions around CGC or hold raw; watch for PSA Value reopening as the trigger to resume bulk grading.
A13: 7 | B13: SPORTS: Panini NFL exclusive ended Mar 31, 2026; first Fanatics NFL product (Topps Chrome Football) ~Apr 15. FIFA World Cup 2026 runs Jun 11-Jul 19; Panini Prizm FIFA WC hobby boxes drop Jun 26. Lock final-year Panini NFL/NBA hobby boxes for finality exposure.
A14: 8 | B14: KEY THRESHOLDS TO WATCH: OP-13 post-restock price (August), PSA Value-tier reopening, the Panini-Fanatics antitrust trial outcome, and whether Pokemon's larger Mega-era print runs soften sealed prices.
A16: Patience pays. 🦞

Sheet Master_Calendar
A1: Master Calendar — April 2026 through March 2029
A2: Every confirmed and projected release and catalyst event. Sorted chronologically. Update Status column as purchases are made.
A4: Date | B4: Category | C4: Product / Event | D4: Publisher | E4: Format | F4: MSRP ($) | G4: Chase / Key Cards | H4: Availability Risk | I4: Action Signal | J4: Buy Window Start | K4: Buy Window End | L4: Priority | M4: Budget ($) | N4: Notes
A5: 46129 | B5: Magic | C5: Secrets of Strixhaven — Prerelease events | D5: Wizards of the Coast | E5: Prerelease Pack | F5: 30 | G5: Mystical Archive reprints, Emeritus of Ideation serialized | H5: Medium | I5: Buy at MSRP on release | J5: 46129 | K5: 46136 | L5: 2 — Strong buy | M5: 30 | N5: Prerelease packs are the cheapest way into SOS chase slots. LGS events at Gamers Guild NWA.
A6: 46136 | B6: Magic | C6: Secrets of Strixhaven — Play Booster Display | D6: Wizards of the Coast | E6: Play Booster Box (30ct) | F6: 165 | G6: Mystical Archive reprints across rarities | H6: Low | I6: Wait 90 days for trough | J6: 46227 | K6: 46319 | L6: 3 — Opportunistic | M6: 120 | N6: Play boosters typically trough 25% below MSRP by T+90. Wait.
A7: 46136 | B7: Magic | C7: Secrets of Strixhaven — Collector Booster Display | D7: Wizards of the Coast | E7: Collector Booster Box (12ct) | F7: 324 | G7: Emeritus of Ideation serialized chase | H7: Medium | I7: Monitor only | J7: 46227 | K7: 46501 | L7: 4 — Monitor | M7: 0 | N7: Above $200/card ceiling. Monitor Collector Booster single pack at ~$27 MSRP instead.
A8: 46136 | B8: Magic | C8: Secrets of Strixhaven — Commander Precons (5 decks) | D8: Wizards of the Coast | E8: Commander Deck | F8: 50 | G8: College-themed reprint packages per deck | H8: Low | I8: Buy at MSRP on release | J8: 46136 | K8: 46197 | L8: 2 — Strong buy | M8: 50 | N8: Commander precons are the single best MSRP buy in MTG. Pick one college theme.
A9: 46136 | B9: Magic | C9: Secrets of Strixhaven — Bundle | D9: Wizards of the Coast | E9: Bundle | F9: 58 | G9: Promo art + accessories | H9: Low | I9: SKIP — do not buy | L9: 5 — Avoid | M9: 0 | N9: Bundles are worst-value at new $58 MSRP. Buy Play Boosters separately if needed.
A10: 46157 | B10: Lorcana | C10: Wilds Unknown Illumineer's Trove | D10: Ravensburger | E10: Illumineer's Trove | F10: 50 | G10: Chapter 10 Enchanted chase cards | H10: Low | I10: Buy at MSRP on release | J10: 46157 | K10: 46188 | L10: 2 — Strong buy | M10: 50 | N10: Illumineer's Trove is best-EV Lorcana SKU. 2 booster packs + starter + accessories.
A11: 46157 | B11: Lorcana | C11: Wilds Unknown — Booster Box | D11: Ravensburger | E11: Booster Box (24 packs) | F11: 145 | G11: Chapter 10 Enchanted cards (1:~3000 pull) | H11: Low | I11: Wait 90 days for trough | J11: 46249 | K11: 46341 | L11: 3 — Opportunistic | M11: 140 | N11: Chapter sets typically trough 15-20% below MSRP at T+90.
A12: 46164 | B12: OnePiece | C12: OP-14 English release (The Cunning Saboteur) | D12: Bandai | E12: Booster Box (24 packs) | F12: 120 | G12: Sabo, Croc, Vivi alternate arts | H12: Medium | I12: Preorder now | J12: 46134 | K12: 46164 | L12: 2 — Strong buy | M12: 120 | N12: English OP releases reliably appreciate. Preorder through Gamers Guild or Collectors Edge.
A13: 46164 | B13: Film | C13: Mandalorian & Grogu theatrical release | D13: Disney/Lucasfilm | E13: Film catalyst | F13: 0 | G13: Drives SWU Grogu/Mando product demand through summer 2026 | I13: Monitor only | J13: 46164 | K13: 46265 | L13: 4 — Monitor | M13: 0 | N13: CATALYST EVENT — not a purchase. Watch SWU Mando/Grogu alt-art singles for buying window.
A14: 46174 | B14: Soccer_WC | C14: Panini World Cup 2026 Sticker Album | D14: Panini | E14: Sticker album + packs | F14: 15 | G14: Complete-album demand pre-tournament | H14: Low | I14: Buy at MSRP on release | J14: 46113 | K14: 46183 | L14: 2 — Strong buy | M14: 30 | N14: Cultural anchor product. Buy album + 20 packs ($30 total) as family activity + sealed hold.
A15: 46184 | B15: Catalyst | C15: FIFA World Cup 2026 kickoff (USA/Mexico/Canada) | D15: FIFA | E15: Global tournament catalyst | F15: 0 | G15: 48 teams, 104 matches, largest WC ever | I15: Monitor only | J15: 46184 | K15: 46222 | L15: 1 — Must buy | M15: 0 | N15: CATALYST — the single biggest soccer card catalyst of the decade. Singles window opens.
A16: 46186 | B16: Magic | C16: Final Fantasy Universes Beyond | D16: Wizards of the Coast | E16: Collector Booster Box | F16: 480 | G16: Cloud, Sephiroth, Tidus legendary variants | H16: High | I16: Preorder now | J16: 46127 | K16: 46186 | L16: 1 — Must buy | M16: 120 | N16: HIGHEST-CONVICTION MTG OF 2026. FF7 Remake/Rebirth residual + crossover demand. Preorder Commander deck at MSRP.
A17: 46186 | B17: Magic | C17: Final Fantasy — Commander Decks | D17: Wizards of the Coast | E17: Commander Deck | F17: 75 | G17: FF-themed commanders, cross-franchise reprints | H17: High | I17: Preorder now | J17: 46127 | K17: 46186 | L17: 1 — Must buy | M17: 75 | N17: Get one FF Commander deck at MSRP — scalper target, will 2x by year-end 2026.
A18: 46188 | B18: Pokemon | C18: Mega Evolution main set (English, est. Destined Horizons) | D18: Pokemon Company | E18: Elite Trainer Box | F18: 50 | G18: Mega Charizard/Mewtwo Special Illustration Rares | H18: High | I18: Preorder now | J18: 46143 | K18: 46188 | L18: 1 — Must buy | M18: 100 | N18: Preorder 2x ETBs through Pokemon Center direct. Scalpers will vacuum Target/Walmart endcaps.
A19: 46188 | B19: Pokemon | C19: Mega Evolution — Booster Bundle (6 packs) | D19: Pokemon Company | E19: Booster Bundle | F19: 27 | G19: Entry-tier sealed | H19: Medium | I19: Buy at MSRP on release | J19: 46188 | K19: 46218 | L19: 3 — Opportunistic | M19: 27 | N19: Good entry SKU. Buy 2-3 if local retailers have stock at MSRP.
A20: 46192 | B20: Baseball | C20: Topps Series 2 (Topps 75th anniversary subsets) | D20: Topps/Fanatics | E20: Hobby Box | F20: 110 | G20: Series 2 RCs, 75th-anniversary commemorative inserts | H20: Low | I20: Buy at MSRP on release | J20: 46192 | K20: 46284 | L20: 3 — Opportunistic | M20: 110 | N20: 2026 is Topps' 75th. Commemorative subsets have historically strong nostalgia resale.
A21: 46222 | B21: Catalyst | C21: FIFA World Cup 2026 Final | D21: FIFA | E21: Tournament close | F21: 0 | G21: Post-tournament correction window opens | I21: Monitor only | J21: 46222 | K21: 46295 | L21: 1 — Must buy | M21: 0 | N21: CATALYST — start buying singles of losing finalists at -20% within 72 hrs of final.
A22: 46223 | B22: Soccer_WC | C22: Panini Prizm World Cup 2026 (Hobby) | D22: Panini | E22: Hobby Box (12 packs) | F22: 350 | G22: Yamal, Bellingham, Mbappé, Haaland base Silver Prizms | H22: High | I22: Preorder now | J22: 46143 | K22: 46223 | L22: 1 — Must buy | M22: 180 | N22: HIGHEST-CONVICTION SOCCER PRODUCT OF THE DECADE. Preorder at authorized dealer. Split 1 box with a trading partner if $350 is over budget.
A23: 46223 | B23: Soccer_WC | C23: Panini Select WC 2026 | D23: Panini | E23: Hobby Box | F23: 280 | G23: Concourse/Premier/Field Level rookie parallels | H23: Medium | I23: Buy at MSRP on release | J23: 46223 | K23: 46315 | L23: 2 — Strong buy | M23: 140 | N23: Tier-2 soccer. Buy 1 box at MSRP or split with trading partner.
A24: 46223 | B24: Soccer_WC | C24: Panini Score + Donruss WC 2026 (retail) | D24: Panini | E24: Retail blaster/mega | F24: 25 | G24: Entry-tier world cup cards | H24: Low | I24: Buy at MSRP on release | J24: 46223 | K24: 46315 | L24: 3 — Opportunistic | M24: 75 | N24: 3 blasters for $75 total. Cheap singles hunting + sealed appreciation after WC ends.
A25: 46228 | B25: Magic | C25: Marvel Spider-Man Universes Beyond (Collector) | D25: Wizards of the Coast | E25: Collector Booster Box | F25: 480 | G25: Spider-Man Collector Edition Commander ($160) | H25: High | I25: Monitor only | J25: 46228 | K25: 46412 | L25: 3 — Opportunistic | M25: 0 | N25: Universes Beyond Marvel crossover. Collector Edition Commander at $160 is the preorder target.
A26: 46228 | B26: Magic | C26: Marvel Spider-Man — Collector Edition Commander | D26: Wizards of the Coast | E26: All-Surge-Foil Commander | F26: 160 | G26: Every card foil, Spider-Man-themed | H26: High | I26: Preorder now | J26: 46167 | K26: 46228 | L26: 2 — Strong buy | M26: 160 | N26: All-foil premium Commander. Marvel IP crossover = high chance of 1.5-2x within 12 months.
A27: 46241 | B27: Baseball | C27: Bowman Chrome flagship | D27: Topps/Fanatics | E27: Hobby Box | F27: 270 | G27: 1st Bowman Chrome Autos: 2026 Draft class + 2025 prospects | H27: Medium | I27: Monitor only | J27: 46241 | K27: 46425 | L27: 3 — Opportunistic | M27: 0 | N27: Box is over $200 ceiling. Buy 1st Bowman Chrome Auto singles of top prospects at T+90 trough instead.
A28: 46242 | B28: Pokemon | C28: Mega Evolution set 2 (English, est. late summer) | D28: Pokemon Company | E28: Elite Trainer Box | F28: 50 | G28: Secondary Mega chase pulls | H28: Medium | I28: Buy at MSRP on release | J28: 46242 | K28: 46334 | L28: 3 — Opportunistic | M28: 50 | N28: Follow-up Mega set. Not scalper-priority — calmer buy window.
A29: 46249 | B29: Magic | C29: Edge of Eternities (sci-fi standard set) | D29: Wizards of the Coast | E29: Play Booster Box | F29: 165 | G29: Original sci-fi IP, spacecraft mechanics | H29: Medium | I29: Wait 90 days for trough | J29: 46341 | K29: 46433 | L29: 3 — Opportunistic | M29: 120 | N29: New standard set. Wait for T+90 trough. Original IP = lower crossover hype than UB.
A30: 46254 | B30: OnePiece | C30: OP-15 English release (est.) | D30: Bandai | E30: Booster Box | F30: 120 | G30: Fifth-anniversary-adjacent alternate arts | H30: Medium | I30: Preorder now | J30: 46204 | K30: 46254 | L30: 2 — Strong buy | M30: 120 | N30: Fifth-anniversary runup begins. Bandai will tease 2027 anniversary products here.
A31: 46270 | B31: Lorcana | C31: Chapter 11 main set (est. name Winterspell) | D31: Ravensburger | E31: Booster Box | F31: 145 | G31: Winter/Frozen-themed Enchanted cards | H31: Low | I31: Buy at MSRP on release | J31: 46270 | K31: 46361 | L31: 3 — Opportunistic | M31: 140 | N31: Frozen IP always performs. D23 September 2026 may drive additional hype.
A32: 46275 | B32: Catalyst | C32: D23 Expo 2026 (Disney fan convention) | D32: Disney | E32: Announcement catalyst | F32: 0 | G32: Lorcana future sets revealed, Disney product roadmap | I32: Monitor only | J32: 46275 | K32: 46279 | L32: 4 — Monitor | M32: 0 | N32: CATALYST — watch for Lorcana set reveals and limited D23-exclusive promos.
A33: 46280 | B33: Basketball | C33: Topps NBA flagship inaugural release | D33: Topps/Fanatics | E33: Hobby Box | F33: 180 | G33: Cooper Flagg + 2025-26 rookie RCs on Topps substrate | H33: High | I33: Preorder now | J33: 46218 | K33: 46280 | L33: 1 — Must buy | M33: 180 | N33: FIRST TOPPS NBA PRODUCT in 10+ years. Cooper Flagg RC is the single most speculated card of 2026.
A34: 46280 | B34: Basketball | C34: 2024-25 Panini Prizm NBA (final Panini year) | D34: Panini | E34: Hobby Box (existing) | F34: 400 | G34: Last licensed Panini Prizm NBA ever | H34: Low | I34: Monitor only | J34: 46132 | K34: 46497 | L34: 2 — Strong buy | M34: 0 | N34: Box over budget. Buy PSA 10 Silver Prizm rookie singles of established stars at <$200 instead. End-of-era premium coming.
A35: 46310 | B35: Pokemon | C35: Pokemon TCG 30th Anniversary Celebration Collection (est.) | D35: Pokemon Company | E35: Special Anniversary Set | F35: 60 | G35: Vintage reprints (Base Charizard, Pikachu), commemorative frames | H35: High | I35: Preorder now | J35: 46249 | K35: 46310 | L35: 1 — Must buy | M35: 120 | N35: ULTRA HIGH CONVICTION. Pokemon TCG debuted October 1996; this is the 30th product. Preorder 2x. Will 2-3x by 2028.
A36: 46317 | B36: Baseball | C36: Topps Update Series (2026) | D36: Topps/Fanatics | E36: Hobby Box | F36: 110 | G36: 2026 rookie RCs: Roman Anthony, Bubba Chandler, Walker Jenkins, Jac Caglianone | H36: Low | I36: Buy at MSRP on release | J36: 46317 | K36: 46409 | L36: 2 — Strong buy | M36: 110 | N36: The 2026 rookie class hits Topps Update. Buy if budget allows; else target rookie singles on the Feb 2027 trough.
A37: 46327 | B37: Magic | C37: Avatar: The Last Airbender Universes Beyond | D37: Wizards of the Coast | E37: Collector Booster Box | F37: 480 | G37: Aang, Zuko, Katara, Toph legendary variants | H37: High | I37: Preorder now | J37: 46266 | K37: 46327 | L37: 2 — Strong buy | M37: 75 | N37: Avatar IP massive crossover. Preorder Commander deck ($75) only — box over budget.
A38: 46327 | B38: Magic | C38: Avatar: The Last Airbender — Commander Decks | D38: Wizards of the Coast | E38: Commander Deck | F38: 75 | G38: Element-themed commanders | H38: High | I38: Preorder now | J38: 46266 | K38: 46327 | L38: 1 — Must buy | M38: 75 | N38: Buy 1 deck at MSRP. Avatar fanbase + MTG crossover = reliable 2x within 18 months.
A39: 46333 | B39: Pokemon | C39: Mega Evolution set 3 (English, late 2026) | D39: Pokemon Company | E39: Elite Trainer Box | F39: 50 | G39: Year-end Mega chase | H39: Medium | I39: Buy at MSRP on release | J39: 46333 | K39: 46425 | L39: 3 — Opportunistic | M39: 50 | N39: Holiday-season release. Retailer stock relatively good; buy at MSRP without urgency.
A40: 46336 | B40: OnePiece | C40: OP-16 The Moment of Decisive Battle (English) | D40: Bandai | E40: Booster Box | F40: 120 | G40: Marco, Ace, Whitebeard Marineford-arc alt arts | H40: Medium | I40: Preorder now | J40: 46275 | K40: 46336 | L40: 2 — Strong buy | M40: 120 | N40: Marineford arc is the most emotionally resonant One Piece arc. Alt arts will drive singles demand.
A41: 46347 | B41: Baseball | C41: Bowman Draft 2026 | D41: Topps/Fanatics | E41: Hobby Box | F41: 160 | G41: 2026 MLB draft class 1st Bowman Chrome Autos | H41: Medium | I41: Monitor only | J41: 46347 | K41: 46528 | L41: 3 — Opportunistic | M41: 0 | N41: Box over budget. Research 2026 draft top-10 picks and target their 1st Bowman Chrome Autos <$100 at T+90 trough.
...

Sheet This_Month
A1: This Month — What to do right now
A2: Live view: every event with a buy window that overlaps the next 45 days, ranked by priority. Uses TODAY() so it updates automatically.
A4: Today's date: | B4: =TODAY() -> 46187
A5: Looking forward: | B5: =TODAY()+45 -> 46232
A7: Priority | B7: Date | C7: Category | D7: Product | E7: Action Signal | F7: Budget ($) | G7: Notes
A8: 2 — Strong buy | B8: 46113 | C8: Soccer_WC | D8: Panini World Cup 2026 Sticker Album | E8: Buy at MSRP on release | F8: 30 | G8: Cultural anchor product. Buy album + 20 packs ($30 total) as family activity + sealed hold.
A9: 1 — Must buy | B9: 46127 | C9: Magic | D9: Final Fantasy Universes Beyond | E9: Preorder now | F9: 120 | G9: HIGHEST-CONVICTION MTG OF 2026. FF7 Remake/Rebirth residual + crossover demand. Preorder Commander deck at MSRP.
A10: 1 — Must buy | B10: 46127 | C10: Magic | D10: Final Fantasy — Commander Decks | E10: Preorder now | F10: 75 | G10: Get one FF Commander deck at MSRP — scalper target, will 2x by year-end 2026.
A11: 2 — Strong buy | B11: 46129 | C11: Magic | D11: Secrets of Strixhaven — Prerelease events | E11: Buy at MSRP on release | F11: 30 | G11: Prerelease packs are the cheapest way into SOS chase slots. LGS events at Gamers Guild NWA.
A12: 2 — Strong buy | B12: 46132 | C12: Basketball | D12: 2024-25 Panini Prizm NBA (final Panini year) | E12: Monitor only | F12: 0 | G12: Box over budget. Buy PSA 10 Silver Prizm rookie singles of established stars at <$200 instead. End-of-era premium coming.
A13: 2 — Strong buy | B13: 46134 | C13: OnePiece | D13: OP-14 English release (The Cunning Saboteur) | E13: Preorder now | F13: 120 | G13: English OP releases reliably appreciate. Preorder through Gamers Guild or Collectors Edge.
A14: 2 — Strong buy | B14: 46136 | C14: Magic | D14: Secrets of Strixhaven — Commander Precons (5 decks) | E14: Buy at MSRP on release | F14: 50 | G14: Commander precons are the single best MSRP buy in MTG. Pick one college theme.
A15: 5 — Avoid | B15: 46136 | C15: Magic | D15: Secrets of Strixhaven — Bundle | E15: SKIP — do not buy | F15: 0 | G15: Bundles are worst-value at new $58 MSRP. Buy Play Boosters separately if needed.
A16: 1 — Must buy | B16: 46143 | C16: Pokemon | D16: Mega Evolution main set (English, est. Destined Horizons) | E16: Preorder now | F16: 100 | G16: Preorder 2x ETBs through Pokemon Center direct. Scalpers will vacuum Target/Walmart endcaps.
A17: 1 — Must buy | B17: 46143 | C17: Soccer_WC | D17: Panini Prizm World Cup 2026 (Hobby) | E17: Preorder now | F17: 180 | G17: HIGHEST-CONVICTION SOCCER PRODUCT OF THE DECADE. Preorder at authorized dealer. Split 1 box with a trading partner if $350 is over budget.
A18: 2 — Strong buy | B18: 46157 | C18: Lorcana | D18: Wilds Unknown Illumineer's Trove | E18: Buy at MSRP on release | F18: 50 | G18: Illumineer's Trove is best-EV Lorcana SKU. 2 booster packs + starter + accessories.
A19: 4 — Monitor | B19: 46164 | C19: Film | D19: Mandalorian & Grogu theatrical release | E19: Monitor only | F19: 0 | G19: CATALYST EVENT — not a purchase. Watch SWU Mando/Grogu alt-art singles for buying window.
... A32: 3 — Opportunistic | B32: 46228 | C32: Magic | D32: Marvel Spider-Man Universes Beyond (Collector) | E32: Monitor only | F32: 0 | G32: Universes Beyond Marvel crossover. Collector Edition Commander at $160 is the preorder target.
A34: How to read this sheet: rows sorted by buy-window start. Scroll down to skip events whose windows have already passed. Re-sort by Date column (col B) to see chronological order.

Sheet Visual_Timeline
A1: Visual Timeline — Quarter-Grouped Event Display
A2: Visual companion to Master_Calendar. Events grouped by calendar quarter with priority-tier color coding. Replaces the standalone HTML Dashboard.
A4: Patience pays. 🦞
A6: 2026 Q2 | B6: 16 events
A7: Date | B7: Category | C7: Product | D7: Action | E7: Priority | F7: Budget
A8: 46129 | B8: Magic | C8: Secrets of Strixhaven — Prerelease events | D8: Buy at MSRP on release | E8: 2 — Strong buy | F8: 30
A9: 46136 | B9: Magic | C9: Secrets of Strixhaven — Commander Precons (5 decks) | D9: Buy at MSRP on release | E9: 2 — Strong buy | F9: 50
A10: 46136 | B10: Magic | C10: Secrets of Strixhaven — Play Booster Display | D10: Wait 90 days for trough | E10: 3 — Opportunistic | F10: 120
A11: 46136 | B11: Magic | C11: Secrets of Strixhaven — Collector Booster Display | D11: Monitor only | E11: 4 — Monitor | F11: 0
A12: 46136 | B12: Magic | C12: Secrets of Strixhaven — Bundle | D12: SKIP — do not buy | E12: 5 — Avoid | F12: 0
A13: 46157 | B13: Lorcana | C13: Wilds Unknown Illumineer's Trove | D13: Buy at MSRP on release | E13: 2 — Strong buy | F13: 50
A14: 46157 | B14: Lorcana | C14: Wilds Unknown — Booster Box | D14: Wait 90 days for trough | E14: 3 — Opportunistic | F14: 140
A15: 46164 | B15: OnePiece | C15: OP-14 English release (The Cunning Saboteur) | D15: Preorder now | E15: 2 — Strong buy | F15: 120
A16: 46164 | B16: Film | C16: Mandalorian & Grogu theatrical release | D16: Monitor only | E16: 4 — Monitor | F16: 0
A17: 46174 | B17: Soccer_WC | C17: Panini World Cup 2026 Sticker Album | D17: Buy at MSRP on release | E17: 2 — Strong buy | F17: 30
A18: 46184 | B18: Catalyst | C18: FIFA World Cup 2026 kickoff (USA/Mexico/Canada) | D18: Monitor only | E18: 1 — Must buy | F18: 0
A19: 46186 | B19: Magic | C19: Final Fantasy Universes Beyond | D19: Preorder now | E19: 1 — Must buy | F19: 120
... A23: 46192 | B23: Baseball | C23: Topps Series 2 (Topps 75th anniversary subsets) | D23: Buy at MSRP on release | E23: 3 — Opportunistic | F23: 110
A25: 2026 Q3 | B25: 14 events
A26: Date | B26: Category | C26: Product | D26: Action | E26: Priority | F26: Budget
A27: 46222 | B27: Catalyst | C27: FIFA World Cup 2026 Final | D27: Monitor only | E27: 1 — Must buy | F27: 0
A28: 46223 | B28: Soccer_WC | C28: Panini Prizm World Cup 2026 (Hobby) | D28: Preorder now | E28: 1 — Must buy | F28: 180
A29: 46223 | B29: Soccer_WC | C29: Panini Select WC 2026 | D29: Buy at MSRP on release | E29: 2 — Strong buy | F29: 140
A30: 46223 | B30: Soccer_WC | C30: Panini Score + Donruss WC 2026 (retail) | D30: Buy at MSRP on release | E30: 3 — Opportunistic | F30: 75
A31: 46228 | B31: Magic | C31: Marvel Spider-Man — Collector Edition Commander | D31: Preorder now | E31: 2 — Strong buy | F31: 160
A32: 46228 | B32: Magic | C32: Marvel Spider-Man Universes Beyond (Collector) | D32: Monitor only | E32: 3 — Opportunistic | F32: 0
A33: 46241 | B33: Baseball | C33: Bowman Chrome flagship | D33: Monitor only | E33: 3 — Opportunistic | F33: 0
A34: 46242 | B34: Pokemon | C34: Mega Evolution set 2 (English, est. late summer) | D34: Buy at MSRP on release | E34: 3 — Opportunistic | F34: 50
A35: 46249 | B35: Magic | C35: Edge of Eternities (sci-fi standard set) | D35: Wait 90 days for trough | E35: 3 — Opportunistic | F35: 120
A36: 46254 | B36: OnePiece | C36: OP-15 English release (est.) | D36: Preorder now | E36: 2 — Strong buy | F36: 120
A37: 46270 | B37: Lorcana | C37: Chapter 11 main set (est. name Winterspell) | D37: Buy at MSRP on release | E37: 3 — Opportunistic | F37: 140
A38: 46275 | B38: Catalyst | C38: D23 Expo 2026 (Disney fan convention) | D38: Monitor only | E38: 4 — Monitor | F38: 0
... A40: 46280 | B40: Basketball | C40: 2024-25 Panini Prizm NBA (final Panini year) | D40: Monitor only | E40: 2 — Strong buy | F40: 0
A42: 2026 Q4 | B42: 9 events
A43: Date | B43: Category | C43: Product | D43: Action | E43: Priority | F43: Budget
A44: 46310 | B44: Pokemon | C44: Pokemon TCG 30th Anniversary Celebration Collection (est.) | D44: Preorder now | E44: 1 — Must buy | F44: 120
A45: 46317 | B45: Baseball | C45: Topps Update Series (2026) | D45: Buy at MSRP on release | E45: 2 — Strong buy | F45: 110
A46: 46327 | B46: Magic | C46: Avatar: The Last Airbender — Commander Decks | D46: Preorder now | E46: 1 — Must buy | F46: 75
A47: 46327 | B47: Magic | C47: Avatar: The Last Airbender Universes Beyond | D47: Preorder now | E47: 2 — Strong buy | F47: 75
A48: 46333 | B48: Pokemon | C48: Mega Evolution set 3 (English, late 2026) | D48: Buy at MSRP on release | E48: 3 — Opportunistic | F48: 50
...

Sheet Pokemon
A1: Pokémon — 35-Month Calendar
A2: Mega Evolution block closure, next block debut, annual special expansions, 30th-anniversary products.
A4: Date | B4: Product | C4: Format | D4: MSRP ($) | E4: Chase / Key Cards | F4: Action Signal | G4: Buy Window | H4: Priority | I4: Budget ($) | J4: Availability | K4: Notes
A5: 46188 | B5: Mega Evolution main set (English, est. Destined Horizons) | C5: Elite Trainer Box | D5: 50 | E5: Mega Charizard/Mewtwo Special Illustration Rares | F5: Preorder now | G5: May 01, 2026 → Jun 15, 2026 | H5: 1 — Must buy | I5: 100 | J5: High | K5: Preorder 2x ETBs through Pokemon Center direct. Scalpers will vacuum Target/Walmart endcaps.
A6: 46188 | B6: Mega Evolution — Booster Bundle (6 packs) | C6: Booster Bundle | D6: 27 | E6: Entry-tier sealed | F6: Buy at MSRP on release | G6: Jun 15, 2026 → Jul 15, 2026 | H6: 3 — Opportunistic | I6: 27 | J6: Medium | K6: Good entry SKU. Buy 2-3 if local retailers have stock at MSRP.
A7: 46242 | B7: Mega Evolution set 2 (English, est. late summer) | C7: Elite Trainer Box | D7: 50 | E7: Secondary Mega chase pulls | F7: Buy at MSRP on release | G7: Aug 08, 2026 → Nov 08, 2026 | H7: 3 — Opportunistic | I7: 50 | J7: Medium | K7: Follow-up Mega set. Not scalper-priority — calmer buy window.
A8: 46310 | B8: Pokemon TCG 30th Anniversary Celebration Collection (est.) | C8: Special Anniversary Set | D8: 60 | E8: Vintage reprints (Base Charizard, Pikachu), commemorative frames | F8: Preorder now | G8: Aug 15, 2026 → Oct 15, 2026 | H8: 1 — Must buy | I8: 120 | J8: High | K8: ULTRA HIGH CONVICTION. Pokemon TCG debuted October 1996; this is the 30th product. Preorder 2x. Will 2-3x by 2028.
A9: 46333 | B9: Mega Evolution set 3 (English, late 2026) | C9: Elite Trainer Box | D9: 50 | E9: Year-end Mega chase | F9: Buy at MSRP on release | G9: Nov 07, 2026 → Feb 07, 2027 | H9: 3 — Opportunistic | I9: 50 | J9: Medium | K9: Holiday-season release. Retailer stock relatively good; buy at MSRP without urgency.
A10: 46402 | B10: Prismatic Evolutions-successor (est. Eevee-focused) | C10: Special Expansion | D10: 55 | E10: High-pull-rate Eeveelution focus set | F10: Preorder now | G10: Nov 15, 2026 → Jan 15, 2027 | H10: 1 — Must buy | I10: 165 | J10: Very High | K10: TOP-3 CONVICTION OF 2027. Prismatic Evolutions 2025 pattern repeats. Buy 3x ETBs through Pokemon Center direct.
A11: 46522 | B11: Mega Evolution set 4 (est.) | C11: Elite Trainer Box | D11: 55 | E11: Block capstone approaching | F11: Buy at MSRP on release | G11: May 15, 2027 → Aug 15, 2027 | H11: 2 — Strong buy | I11: 55 | J11: Medium | K11: Block is aging. Last 1-2 Mega ETBs often appreciate on block-end. Buy 1.
A12: 46614 | B12: Mega Evolution final block set (est.) | C12: Elite Trainer Box | D12: 55 | E12: Block-capstone chase cards | F12: Preorder now | G12: Jun 15, 2027 → Aug 15, 2027 | H12: 1 — Must buy | I12: 110 | J12: High | K12: LAST Mega Evolution set. Block-end sealed appreciation pattern is most reliable in Pokemon. Buy 2x.
A13: 46645 | B13: New block debut (est., possibly Pokemon Legends Z-A tie-in) | C13: Elite Trainer Box | D13: 55 | E13: New generation chase | F13: Preorder now | G13: Jul 15, 2027 → Sep 15, 2027 | H13: 1 — Must buy | I13: 165 | J13: Very High | K13: New Pokemon block debut. 2023 Scarlet & Violet pattern suggests high scalper pressure. 3x ETBs.
A14: 46767 | B14: Annual special expansion (est., Eevee/Generation-1 focus) | C14: Special Expansion | D14: 55 | E14: High-pull-rate focus set | F14: Preorder now | G14: Nov 15, 2027 → Jan 15, 2028 | H14: 1 — Must buy | I14: 165 | J14: Very High | K14: Prismatic-pattern January release. 3x ETBs. Scalper-target tier.
A15: 46919 | B15: New block main set 2028 (est.) | C15: Elite Trainer Box | D15: 55 | E15: Mid-block chase cards | F15: Buy at MSRP on release | G15: Jun 15, 2028 → Sep 15, 2028 | H15: 2 — Strong buy | I15: 110 | J15: High | K15: New block mid-period releases. Buy 2x ETB.
A16: 47164 | B16: Pokemon TCG 33-year product (est.) | C16: Standard set | D16: 55 | E16: Mid-2029 block | F16: Buy at MSRP on release | G16: Feb 15, 2029 → May 15, 2029 | H16: 3 — Opportunistic | I16: 55 | J16: Medium | K16: Standard release. No anniversary catalyst; standard cadence.
A18: TOTALS | D18: =SUM(D5:D16) -> 622 | I18: =SUM(I5:I16) -> 1172

Sheet Magic
A1: Magic: The Gathering — 35-Month Calendar
A2: Standard rotations, Universes Beyond crossovers (FF, Marvel, Avatar), Modern Horizons 4, 35th-anniversary masters.
A4: Date | B4: Product | C4: Format | D4: MSRP ($) | E4: Chase / Key Cards | F4: Action Signal | G4: Buy Window | H4: Priority | I4: Budget ($) | J4: Availability | K4: Notes
A5: 46129 | B5: Secrets of Strixhaven — Prerelease events | C5: Prerelease Pack | D5: 30 | E5: Mystical Archive reprints, Emeritus of Ideation serialized | F5: Buy at MSRP on release | G5: Apr 17, 2026 → Apr 24, 2026 | H5: 2 — Strong buy | I5: 30 | J5: Medium | K5: Prerelease packs are the cheapest way into SOS chase slots. LGS events at Gamers Guild NWA.
A6: 46136 | B6: Secrets of Strixhaven — Play Booster Display | C6: Play Booster Box (30ct) | D6: 165 | E6: Mystical Archive reprints across rarities | F6: Wait 90 days for trough | G6: Jul 24, 2026 → Oct 24, 2026 | H6: 3 — Opportunistic | I6: 120 | J6: Low | K6: Play boosters typically trough 25% below MSRP by T+90. Wait.
A7: 46136 | B7: Secrets of Strixhaven — Collector Booster Display | C7: Collector Booster Box (12ct) | D7: 324 | E7: Emeritus of Ideation serialized chase | F7: Monitor only | G7: Jul 24, 2026 → Apr 24, 2027 | H7: 4 — Monitor | I7: 0 | J7: Medium | K7: Above $200/card ceiling. Monitor Collector Booster single pack at ~$27 MSRP instead.
A8: 46136 | B8: Secrets of Strixhaven — Commander Precons (5 decks) | C8: Commander Deck | D8: 50 | E8: College-themed reprint packages per deck | F8: Buy at MSRP on release | G8: Apr 24, 2026 → Jun 24, 2026 | H8: 2 — Strong buy | I8: 50 | J8: Low | K8: Commander precons are the single best MSRP buy in MTG. Pick one college theme.
A9: 46136 | B9: Secrets of Strixhaven — Bundle | C9: Bundle | D9: 58 | E9: Promo art + accessories | F9: SKIP — do not buy | H9: 5 — Avoid | I9: 0 | J9: Low | K9: Bundles are worst-value at new $58 MSRP. Buy Play Boosters separately if needed.
A10: 46186 | B10: Final Fantasy Universes Beyond | C10: Collector Booster Box | D10: 480 | E10: Cloud, Sephiroth, Tidus legendary variants | F10: Preorder now | G10: Apr 15, 2026 → Jun 13, 2026 | H10: 1 — Must buy | I10: 120 | J10: High | K10: HIGHEST-CONVICTION MTG OF 2026. FF7 Remake/Rebirth residual + crossover demand. Preorder Commander deck at MSRP.
A11: 46186 | B11: Final Fantasy — Commander Decks | C11: Commander Deck | D11: 75 | E11: FF-themed commanders, cross-franchise reprints | F11: Preorder now | G11: Apr 15, 2026 → Jun 13, 2026 | H11: 1 — Must buy | I11: 75 | J11: High | K11: Get one FF Commander deck at MSRP — scalper target, will 2x by year-end 2026.
A12: 46228 | B12: Marvel Spider-Man Universes Beyond (Collector) | C12: Collector Booster Box | D12: 480 | E12: Spider-Man Collector Edition Commander ($160) | F12: Monitor only | G12: Jul 25, 2026 → Jan 25, 2027 | H12: 3 — Opportunistic | I12: 0 | J12: High | K12: Universes Beyond Marvel crossover. Collector Edition Commander at $160 is the preorder target.
A13: 46228 | B13: Marvel Spider-Man — Collector Edition Commander | C13: All-Surge-Foil Commander | D13: 160 | E13: Every card foil, Spider-Man-themed | F13: Preorder now | G13: May 25, 2026 → Jul 25, 2026 | H13: 2 — Strong buy | I13: 160 | J13: High | K13: All-foil premium Commander. Marvel IP crossover = high chance of 1.5-2x within 12 months.
A14: 46249 | B14: Edge of Eternities (sci-fi standard set) | C14: Play Booster Box | D14: 165 | E14: Original sci-fi IP, spacecraft mechanics | F14: Wait 90 days for trough | G14: Nov 15, 2026 → Feb 15, 2027 | H14: 3 — Opportunistic | I14: 120 | J14: Medium | K14: New standard set. Wait for T+90 trough. Original IP = lower crossover hype than UB.
A15: 46327 | B15: Avatar: The Last Airbender Universes Beyond | C15: Collector Booster Box | D15: 480 | E15: Aang, Zuko, Katara, Toph legendary variants | F15: Preorder now | G15: Sep 01, 2026 → Nov 01, 2026 | H15: 2 — Strong buy | I15: 75 | J15: High | K15: Avatar IP massive crossover. Preorder Commander deck ($75) only — box over budget.
A16: 46327 | B16: Avatar: The Last Airbender — Commander Decks | C16: Commander Deck | D16: 75 | E16: Element-themed commanders | F16: Preorder now | G16: Sep 01, 2026 → Nov 01, 2026 | H16: 1 — Must buy | I16: 75 | J16: High | K16: Buy 1 deck at MSRP. Avatar fanbase + MTG crossover = reliable 2x within 18 months.
A17: 46433 | B17: Innistrad / horror-themed spring 2027 set (est.) | C17: Play Booster Box | D17: 165 | E17: TBD spring 2027 | F17: Wait 90 days for trough | G17: May 15, 2027 → Aug 15, 2027 | H17: 4 — Monitor | I17: 0 | J17: Low | K17: Monitor reveals March-April 2027. Wait for product announcement before committing budget.
A18: 46497 | B18: Spring 2027 standard set (est.) | C18: Play Booster Box | D18: 165 | E18: TBD | F18: Monitor only | G18: Apr 20, 2027 → Jul 20, 2027 | H18: 4 — Monitor | I18: 0 | J18: Low | K18: Await announcement. Generic buy-timing rules apply.
A19: 46553 | B19: Modern Horizons 4 (est., 3-year MH cadence) | C19: Collector Booster Box | D19: 550 | E19: Modern-format power cards, serialized retro | F19: Preorder now | G19: Apr 15, 2027 → Jun 15, 2027 | H19: 1 — Must buy | I19: 0 | J19: High | K19: MH4 box over budget. Watch for single-card Modern chase pieces <$200 in collector boosters.
A20: 46675 | B20: Universes Beyond fall 2027 (Star Wars speculated) | C20: Collector Booster Box | D20: 480 | E20: Likely Star Wars IP (if confirmed) | F20: Monitor only | G20: Aug 15, 2027 → Oct 15, 2027 | H20: 2 — Strong buy | I20: 75 | J20: Very High | K20: If Star Wars UB confirmed, preorder 1 Commander deck at MSRP.
A21: 46772 | B21: Spring 2028 standard set (est.) | C21: Play Booster Box | D21: 165 | E21: TBD | F21: Monitor only | G21: Jan 20, 2028 → Apr 20, 2028 | H21: 4 — Monitor | I21: 0 | J21: Low | K21: Await announcement.
... A23: 47197 | B23: Universes Beyond spring 2029 (est.) | C23: Collector Booster Box | D23: 500 | E23: TBD IP | F23: Monitor only | G23: Jan 20, 2029 → Mar 20, 2029 | H23: 3 — Opportunistic | I23: 75 | J23: High | K23: Watch announcement. If Assassin's Creed, Stranger Things, or anime IP = preorder Commander.
A25: TOTALS | D25: =SUM(D5:D23) -> 5117 | I25: =SUM(I5:I23) -> 1125

Sheet OnePiece
A1: One Piece TCG — 35-Month Calendar
A2: Standard Bandai quarterly releases plus July 2027 manga-30th + TCG-5th anniversary double catalyst.
A4: Date | B4: Product | C4: Format | D4: MSRP ($) | E4: Chase / Key Cards | F4: Action Signal | G4: Buy Window | H4: Priority | I4: Budget ($) | J4: Availability | K4: Notes
A5: 46164 | B5: OP-14 English release (The Cunning Saboteur) | C5: Booster Box (24 packs) | D5: 120 | E5: Sabo, Croc, Vivi alternate arts | F5: Preorder now | G5: Apr 22, 2026 → May 22, 2026 | H5: 2 — Strong buy | I5: 120 | J5: Medium | K5: English OP releases reliably appreciate. Preorder through Gamers Guild or Collectors Edge.
A6: 46254 | B6: OP-15 English release (est.) | C6: Booster Box | D6: 120 | E6: Fifth-anniversary-adjacent alternate arts | F6: Preorder now | G6: Jul 01, 2026 → Aug 20, 2026 | H6: 2 — Strong buy | I6: 120 | J6: Medium | K6: Fifth-anniversary runup begins. Bandai will tease 2027 anniversary products here.
A7: 46336 | B7: OP-16 The Moment of Decisive Battle (English) | C7: Booster Box | D7: 120 | E7: Marco, Ace, Whitebeard Marineford-arc alt arts | F7: Preorder now | G7: Sep 10, 2026 → Nov 10, 2026 | H7: 2 — Strong buy | I7: 120 | J7: Medium | K7: Marineford arc is the most emotionally resonant One Piece arc. Alt arts will drive singles demand.
A8: 46569 | B8: One Piece TCG 5th Anniversary window | C8: Anniversary products | D8: 100 | E8: Fifth-anniversary alternate arts, reprint chase sets | F8: Preorder now | G8: May 01, 2027 → Jul 31, 2027 | H8: 1 — Must buy | I8: 200 | J8: High | K8: DOUBLE CATALYST. OP manga also turns 30 in July 2027. Budget 2 purchases: anniversary booster + themed deck.
A9: 47072 | B9: OP-22 or anniversary-continuing (est.) | C9: Booster Box | D9: 130 | E9: Mid-to-late 2028 meta set | F9: Buy at MSRP on release | G9: Nov 15, 2028 → Feb 15, 2029 | H9: 3 — Opportunistic | I9: 130 | J9: Medium | K9: Standard quarterly cadence. MSRP buy.
A11: TOTALS | D11: =SUM(D5:D9) -> 590 | I11: =SUM(I5:I9) -> 690

Sheet Lorcana
A1: Disney Lorcana — 35-Month Calendar
A2: Quarterly Ravensburger releases + D23 2026 reveal window + 5-year anniversary in 2028.
A4: Date | B4: Product | C4: Format | D4: MSRP ($) | E4: Chase / Key Cards | F4: Action Signal | G4: Buy Window | H4: Priority | I4: Budget ($) | J4: Availability | K4: Notes
A5: 46157 | B5: Wilds Unknown Illumineer's Trove | C5: Illumineer's Trove | D5: 50 | E5: Chapter 10 Enchanted chase cards | F5: Buy at MSRP on release | G5: May 15, 2026 → Jun 15, 2026 | H5: 2 — Strong buy | I5: 50 | J5: Low | K5: Illumineer's Trove is best-EV Lorcana SKU. 2 booster packs + starter + accessories.
A6: 46157 | B6: Wilds Unknown — Booster Box | C6: Booster Box (24 packs) | D6: 145 | E6: Chapter 10 Enchanted cards (1:~3000 pull) | F6: Wait 90 days for trough | G6: Aug 15, 2026 → Nov 15, 2026 | H6: 3 — Opportunistic | I6: 140 | J6: Low | K6: Chapter sets typically trough 15-20% below MSRP at T+90.
A7: 46270 | B7: Chapter 11 main set (est. name Winterspell) | C7: Booster Box | D7: 145 | E7: Winter/Frozen-themed Enchanted cards | F7: Buy at MSRP on release | G7: Sep 05, 2026 → Dec 05, 2026 | H7: 3 — Opportunistic | I7: 140 | J7: Low | K7: Frozen IP always performs. D23 September 2026 may drive additional hype.
A8: 46471 | B8: Chapter 13 (est.) | C8: Booster Box | D8: 150 | E8: Spring 2027 Enchanted chase | F8: Buy at MSRP on release | G8: Mar 25, 2027 → Jun 25, 2027 | H8: 3 — Opportunistic | I8: 145 | J8: Low | K8: Standard Lorcana quarterly cadence.
A9: 46822 | B9: Chapter 15 or 5th Anniversary premium set (est.) | C9: Anniversary product | D9: 75 | E9: Lorcana 5-year anniversary (launched Aug 2023) | F9: Preorder now | G9: Jan 10, 2028 → Mar 10, 2028 | H9: 1 — Must buy | I9: 75 | J9: High | K9: Lorcana 5-year anniversary catalyst. Plausible premium-reprint master set.
A11: TOTALS | D11: =SUM(D5:D9) -> 565 | I11: =SUM(I5:I9) -> 550

Sheet YuGiOh
A1: Yu-Gi-Oh! — 35-Month Calendar
A2: Standard Konami cadence with major 30th-anniversary catalyst late 2028 → early 2029.
A4: Date | B4: Product | C4: Format | D4: MSRP ($) | E4: Chase / Key Cards | F4: Action Signal | G4: Buy Window | H4: Priority | I4: Budget ($) | J4: Availability | K4: Notes
A5: 47041 | B5: Yu-Gi-Oh 30th Anniversary pre-announcement products | C5: Anniversary Rarity Collection | D5: 80 | E5: Vintage reprints + Quarter Century Secret Rares | F5: Preorder now | G5: Aug 15, 2028 → Oct 15, 2028 | H5: 1 — Must buy | I5: 160 | J5: High | K5: Konami 25th Anniversary Rarity Collection drove ATH Yu-Gi-Oh prices in 2023-24. 30th repeats this pattern.
A6: 47133 | B6: Yu-Gi-Oh 30th Anniversary main launch products | C6: Anniversary Special Set | D6: 100 | E6: Dark Magician, Blue-Eyes, Exodia premium reprints | F6: Preorder now | G6: Nov 15, 2028 → Jan 15, 2029 | H6: 1 — Must buy | I6: 200 | J6: Very High | K6: MAJOR CATALYST. Max budget deployment. Buy 2 sealed products; grade resale potential is highest-conviction in YGO history.
A8: TOTALS | D8: =SUM(D5:D6) -> 180 | I8: =SUM(I5:I6) -> 360

Sheet Baseball
A1: Baseball Cards — 35-Month Calendar
A2: Topps/Fanatics annual cadence, Jackie Robinson 80th in 2027, Bowman Chrome prospect autos.
A4: Date | B4: Product | C4: Format | D4: MSRP ($) | E4: Chase / Key Cards | F4: Action Signal | G4: Buy Window | H4: Priority | I4: Budget ($) | J4: Availability | K4: Notes
A5: 46192 | B5: Topps Series 2 (Topps 75th anniversary subsets) | C5: Hobby Box | D5: 110 | E5: Series 2 RCs, 75th-anniversary commemorative inserts | F5: Buy at MSRP on release | G5: Jun 19, 2026 → Sep 19, 2026 | H5: 3 — Opportunistic | I5: 110 | J5: Low | K5: 2026 is Topps' 75th. Commemorative subsets have historically strong nostalgia resale.
A6: 46241 | B6: Bowman Chrome flagship | C6: Hobby Box | D6: 270 | E6: 1st Bowman Chrome Autos: 2026 Draft class + 2025 prospects | F6: Monitor only | G6: Aug 07, 2026 → Feb 07, 2027 | H6: 3 — Opportunistic | I6: 0 | J6: Medium | K6: Box is over $200 ceiling. Buy 1st Bowman Chrome Auto singles of top prospects at T+90 trough instead.
A7: 46317 | B7: Topps Update Series (2026) | C7: Hobby Box | D7: 110 | E7: 2026 rookie RCs: Roman Anthony, Bubba Chandler, Walker Jenkins, Jac Caglianone | F7: Buy at MSRP on release | G7: Oct 22, 2026 → Jan 22, 2027 | H7: 2 — Strong buy | I7: 110 | J7: Low | K7: The 2026 rookie class hits Topps Update. Buy if budget allows; else target rookie singles on the Feb 2027 trough.
A8: 46347 | B8: Bowman Draft 2026 | C8: Hobby Box | D8: 160 | E8: 2026 MLB draft class 1st Bowman Chrome Autos | F8: Monitor only | G8: Nov 21, 2026 → May 21, 2027 | H8: 3 — Opportunistic | I8: 0 | J8: Medium | K8: Box over budget. Research 2026 draft top-10 picks and target their 1st Bowman Chrome Autos <$100 at T+90 trough.
A9: 46414 | B9: Topps Series 1 2027 | C9: Hobby Box | D9: 110 | E9: Rookie class standardization | F9: Buy at MSRP on release | G9: Jan 27, 2027 → Apr 27, 2027 | H9: 3 — Opportunistic | I9: 110 | J9: Low | K9: Standard annual release. MSRP if local LGS stocks.
A10: 46460 | B10: Topps Heritage 2027 | C10: Hobby Box | D10: 120 | E10: Nostalgic design rookies | F10: Buy at MSRP on release | G10: Mar 14, 2027 → Jun 14, 2027 | H10: 3 — Opportunistic | I10: 120 | J10: Low | K10: Heritage retains nostalgic appeal. Standard annual. MSRP buy.
A11: 46696 | B11: Bowman Draft 2027 | C11: Hobby Box | D11: 160 | E11: 2027 MLB draft class RC autos | F11: Monitor only | G11: Nov 05, 2027 → May 05, 2028 | H11: 3 — Opportunistic | I11: 0 | J11: Medium | K11: Target top-10-pick 1st Bowman Chrome Auto singles <$100 at T+90.
A12: 46858 | B12: Topps Series 1 2028 + Topps Update 2027 retail | C12: Hobby Box | D12: 110 | E12: Standard annual | F12: Buy at MSRP on release | G12: Apr 15, 2028 → Jul 15, 2028 | H12: 3 — Opportunistic | I12: 110 | J12: Low | K12: Standard annual. Build ongoing vintage-RC exposure.
A13: 47088 | B13: High-end Topps Dynasty/Five Star/Transcendent 2028 | C13: Premium Boxes | D13: 400 | E13: Premium autos | F13: Monitor only | G13: Dec 01, 2028 → Jun 01, 2029 | H13: 4 — Monitor | I13: 0 | J13: Low | K13: Premium boxes vastly over $200 budget. Monitor for singles only.
A15: TOTALS | D15: =SUM(D5:D13) -> 1550 | I15: =SUM(I5:I13) -> 560

Sheet Basketball
A1: Basketball Cards — 35-Month Calendar
A2: Topps NBA debut 2026, final Panini Prizm 2024-25, Cooper Flagg RC catalyst, NBA 80th anniversary.
A4: Date | B4: Product | C4: Format | D4: MSRP ($) | E4: Chase / Key Cards | F4: Action Signal | G4: Buy Window | H4: Priority | I4: Budget ($) | J4: Availability | K4: Notes
A5: 46280 | B5: Topps NBA flagship inaugural release | C5: Hobby Box | D5: 180 | E5: Cooper Flagg + 2025-26 rookie RCs on Topps substrate | F5: Preorder now | G5: Jul 15, 2026 → Sep 15, 2026 | H5: 1 — Must buy | I5: 180 | J5: High | K5: FIRST TOPPS NBA PRODUCT in 10+ years. Cooper Flagg RC is the single most speculated card of 2026.
A6: 46280 | B6: 2024-25 Panini Prizm NBA (final Panini year) | C6: Hobby Box (existing) | D6: 400 | E6: Last licensed Panini Prizm NBA ever | F6: Monitor only | G6: Apr 20, 2026 → Apr 20, 2027 | H6: 2 — Strong buy | I6: 0 | J6: Low | K6: Box over budget. Buy PSA 10 Silver Prizm rookie singles of established stars at <$200 instead. End-of-era premium coming.
A7: 47011 | B7: Topps NBA 2028-29 flagship | C7: Hobby Box | D7: 180 | E7: 2028 NBA rookie class (AJ Dybantsa, Cameron Boozer, Darryn Peterson) | F7: Preorder now | G7: Jul 15, 2028 → Sep 15, 2028 | H7: 1 — Must buy | I7: 180 | J7: High | K7: 2028 class top-3 picks are generational. Preorder hobby box; split with partner if budget is tight.
A9: TOTALS | D9: =SUM(D5:D7) -> 760 | I9: =SUM(I5:I7) -> 360

Sheet Football
A1: Football Cards — 35-Month Calendar
A2: Topps NFL debut late 2026, final Panini Prizm 2025, Super Bowls LXI/LXII/LXIII catalysts.
A4: Date | B4: Product | C4: Format | D4: MSRP ($) | E4: Chase / Key Cards | F4: Action Signal | G4: Buy Window | H4: Priority | I4: Budget ($) | J4: Availability | K4: Notes
A5: 46361 | B5: Topps NFL flagship inaugural (est.) | C5: Hobby Box | D5: 180 | E5: Cam Ward, Travis Hunter, Abdul Carter on Topps NFL substrate | F5: Preorder now | G5: Oct 05, 2026 → Dec 05, 2026 | H5: 1 — Must buy | I5: 180 | J5: High | K5: FIRST TOPPS NFL since 2015. 2025 rookie class' first licensed Topps appearance.
A6: 46366 | B6: 2025 Panini Prizm NFL (final Panini year) | C6: Hobby Box (existing) | D6: 380 | E6: Final licensed Panini Prizm NFL | F6: Monitor only | G6: Jun 15, 2026 → Feb 15, 2027 | H6: 2 — Strong buy | I6: 0 | J6: Low | K6: Box over budget. Target 2025 Panini Prizm Silver Prizm rookies of Cam Ward/Travis Hunter <$150 raw.
A7: 46425 | B7: Super Bowl LXI (Inglewood, CA) | C7: Championship catalyst | D7: 0 | E7: Winning team rookies get 30-day price spike | F7: Monitor only | G7: Feb 07, 2027 → Mar 07, 2027 | H7: 4 — Monitor | I7: 0 | K7: CATALYST — sell any Super Bowl winner rookie holdings in the 21-day window after the game.
A8: 46789 | B8: Super Bowl LXII (New Orleans) | C8: Championship catalyst | D8: 0 | E8: Winning team rookies spike | F8: Monitor only | G8: Feb 06, 2028 → Mar 06, 2028 | H8: 4 — Monitor | I8: 0 | K8: CATALYST — sell any SB winner rookies in 21-day post-game window.
A9: 47153 | B9: Super Bowl LXIII (Santa Clara) | C9: Championship catalyst | D9: 0 | E9: Rookie spike pattern | F9: Monitor only | G9: Feb 04, 2029 → Mar 04, 2029 | H9: 4 — Monitor | I9: 0 | K9: CATALYST — sell SB winner rookies in 21-day post-game window.
A11: TOTALS | D11: =SUM(D5:D9) -> 560 | I11: =SUM(I5:I9) -> 180

Sheet Soccer_WC
A1: Soccer & World Cup — 35-Month Calendar
A2: FIFA World Cup 2026 (the single biggest card catalyst of the decade), Euro 2028, Women's WC 2027.
A4: Date | B4: Product | C4: Format | D4: MSRP ($) | E4: Chase / Key Cards | F4: Action Signal | G4: Buy Window | H4: Priority | I4: Budget ($) | J4: Availability | K4: Notes
A5: 46174 | B5: Panini World Cup 2026 Sticker Album | C5: Sticker album + packs | D5: 15 | E5: Complete-album demand pre-tournament | F5: Buy at MSRP on release | G5: Apr 01, 2026 → Jun 10, 2026 | H5: 2 — Strong buy | I5: 30 | J5: Low | K5: Cultural anchor product. Buy album + 20 packs ($30 total) as family activity + sealed hold.
A6: 46223 | B6: Panini Prizm World Cup 2026 (Hobby) | C6: Hobby Box (12 packs) | D6: 350 | E6: Yamal, Bellingham, Mbappé, Haaland base Silver Prizms | F6: Preorder now | G6: May 01, 2026 → Jul 20, 2026 | H6: 1 — Must buy | I6: 180 | J6: High | K6: HIGHEST-CONVICTION SOCCER PRODUCT OF THE DECADE. Preorder at authorized dealer. Split 1 box with a trading partner if $350 is over budget.
A7: 46223 | B7: Panini Select WC 2026 | C7: Hobby Box | D7: 280 | E7: Concourse/Premier/Field Level rookie parallels | F7: Buy at MSRP on release | G7: Jul 20, 2026 → Oct 20, 2026 | H7: 2 — Strong buy | I7: 140 | J7: Medium | K7: Tier-2 soccer. Buy 1 box at MSRP or split with trading partner.
A8: 46223 | B8: Panini Score + Donruss WC 2026 (retail) | C8: Retail blaster/mega | D8: 25 | E8: Entry-tier world cup cards | F8: Buy at MSRP on release | G8: Jul 20, 2026 → Oct 20, 2026 | H8: 3 — Opportunistic | I8: 75 | J8: Low | K8: 3 blasters for $75 total. Cheap singles hunting + sealed appreciation after WC ends.
A9: 46949 | B9: Post-Euro 2028 Topps Chrome UEFA 2027-28 | C9: Hobby Box | D9: 180 | E9: Euro-adjacent singles premium | F9: Monitor only | G9: Jul 15, 2028 → Oct 15, 2028 | H9: 3 — Opportunistic | I9: 0 | J9: Medium | K9: Tournament residual product. Target Yamal/Bellingham 1st autos in singles market.
A11: TOTALS | D11: =SUM(D5:D9) -> 850 | I11: =SUM(I5:I9) -> 425

Sheet Catalysts
A1: Catalyst Calendar — Events that Move Prices
A2: Anniversaries, tournaments, film releases, license transitions. Not purchases themselves — they dictate when singles/sealed of OTHER products move.
A4: Date | B4: Event | C4: Category Impact | D4: Lead Time | E4: Strategy
A5: 46164 | B5: Mandalorian & Grogu theatrical release | C5: Star Wars Unlimited | D5: 4-8 weeks | E5: Buy Grogu/Mando alt-art singles 6 weeks before film; sell 4 weeks after opening.
A6: 46184 | B6: FIFA World Cup 2026 kickoff (USA/Mexico/Canada) | C6: All soccer cards | D6: 3-6 months | E6: Position Yamal, Bellingham, Mbappé, Haaland singles BEFORE tournament. Add USMNT for home-soil bump.
A7: 46222 | B7: World Cup 2026 Final | C7: All soccer cards — correction window | D7: 72 hours | E7: Buy losing-finalist singles within 72hrs of final (typically -20% immediately).
A8: 46275 | B8: D23 Expo 2026 (Disney fan event) | C8: Disney Lorcana + related | D8: 0-30 days | E8: Monitor for set announcements. Limited D23-exclusive promos scalp heavily.
A9: 46296 | B9: Pokémon TCG 30th anniversary window | C9: Pokémon sealed + vintage WOTC | D9: 6-12 months | E9: Preorder any anniversary product. Vintage WOTC cards typically rally 15-30% during anniversary windows.
A10: 46425 | B10: Super Bowl LXI (Inglewood) | C10: NFL RCs of competing teams | D10: 2-4 weeks post | E10: Sell winning team rookies in 21 days after SB (typical +15-25% spike).
A11: 46492 | B11: Jackie Robinson 80th Anniversary (April 15) | C11: Vintage baseball + Robinson-specific | D11: 6 weeks | E11: Robinson PSA-graded vintage typically rallies. Topps issues 80th-commemorative insert subsets.
A12: 46539 | B12: FIFA Women's World Cup 2027 (Brazil) | C12: Soccer cards — women's | D12: 3-5 months | E12: Position Putellas, Bonmatí, Kerr, Trinity Rodman BEFORE tournament.
A13: 46569 | B13: One Piece TCG 5th anniversary + manga 30th | C13: One Piece TCG (double catalyst) | D13: 6-12 months | E13: Highest-confidence OP window. Alt arts typically 2-3x during anniversary.
A14: 46722 | B14: NBA 80th anniversary season (2026-27) | C14: NBA vintage + commemorative inserts | D14: 12 months | E14: Jordan/Kobe/Lebron commemorative subsets issued. PSA vintage rally possible.
A15: 46789 | B15: Super Bowl LXII (New Orleans) | C15: NFL RCs of competing teams | D15: 21-day spike | E15: Standard SB playbook: sell winner rookies in 21 days.
A16: 46813 | B16: Lorcana 5-year anniversary (launched August 2023) | C16: Lorcana premium sets | D16: 6-9 months | E16: Plausible premium-reprint master set. Watch for announcement Q1 2028.
... A21: 47153 | B21: Super Bowl LXIII (Santa Clara) | C21: NFL RCs of competing teams | D21: 21-day spike | E21: Standard SB playbook.

Sheet Scalper_Watchlist
A1: Scalper Watchlist — MSRP Targets During Drop Windows
A2: SKUs known to sell out at retail in minutes and trade at 2-5x MSRP within 30 days. These are the OpenClaw Retail Drop Monitor primary targets.
A4: Date | B4: Product | C4: Retailers | D4: MSRP | E4: Expected Day-30 Price | F4: Monitoring Channel | G4: Implied Multiple
A5: 46186 | B5: MTG Final Fantasy Collector Booster single pack | C5: Target, Walmart, Amazon | D5: 40 | E5: 75 | F5: OpenClaw Retail Drop Monitor + Discord #mtg-drops | G5: =E5/D5 -> 1.875
A6: 46188 | B6: Pokémon Mega Evolution ETB (Charizard/Mewtwo lineage) | C6: Pokemon Center, Target endcap | D6: 50 | E6: 110 | F6: Pokemon Center direct + Target app alerts via OpenClaw | G6: =E6/D6 -> 2.2
A7: 46223 | B7: Panini Prizm World Cup 2026 hobby box | C7: Dave & Adam's, Blowout, Steel City | D7: 350 | E7: 550 | F7: Licensed dealer pre-order alerts | G7: =E7/D7 -> 1.5714286
A8: 46310 | B8: Pokémon TCG 30th Anniversary Celebration Collection | C8: Pokemon Center, Target, Walmart | D8: 60 | E8: 180 | F8: Pokemon Center push alerts (mandatory membership) | G8: =E8/D8 -> 3
A9: 46361 | B9: Topps NFL flagship inaugural hobby box | C9: Fanatics, Target, LGS | D9: 180 | E9: 320 | F9: Fanatics Collect + LGS Gamers Guild preorder list | G9: =E9/D9 -> 1.7777778
A10: 46402 | B10: Prismatic Evolutions-successor Pokémon ETB | C10: Pokemon Center, all mass retail | D10: 55 | E10: 160 | F10: HIGH PRIORITY. OpenClaw Monitor + multi-retailer + Pokemon Center direct | G10: =E10/D10 -> 2.9090909
A11: 46569 | B11: One Piece 5th Anniversary premium products | C11: Bandai direct, Japanese proxies | D11: 100 | E11: 200 | F11: Buyee/Zenmarket Japanese drop + Bandai TCG+ app | G11: =E11/D11 -> 2
A12: 46767 | B12: Annual Pokemon special expansion (Prismatic-pattern repeat) | C12: Pokemon Center, Target, Walmart | D12: 55 | E12: 150 | F12: Pokemon Center direct | G12: =E12/D12 -> 2.7272727
A13: 46980 | B13: MTG 35th Anniversary masters Commander boxed set | C13: Wizards direct + LGS | D13: 100 | E13: 250 | F13: Wizards announcement list + LGS preorder | G13: =E13/D13 -> 2.5
A14: 47011 | B14: Topps NBA 2028-29 flagship (AJ Dybantsa RC year) | C14: Fanatics Collect + LGS | D14: 180 | E14: 400 | F14: Fanatics pre-order | G14: =E14/D14 -> 2.2222222
A15: 47133 | B15: Yu-Gi-Oh 30th Anniversary Rarity Collection-equivalent | C15: Konami direct + LGS | D15: 80 | E15: 250 | F15: Konami TCG alerts + LGS preorder | G15: =E15/D15 -> 3.125

Sheet Reprint_Risk
A1: Reprint Risk — Products/Cards to AVOID Buying Now
A2: Reprints expected in the 35-month window. Buying raw near-mint singles of these is value-destroying — wait for the reprint and buy post-release.
A4: Category | B4: At-Risk Cards/Products | C4: Expected Reprint Window | D4: Reprint Vehicle | E4: What to Do Instead
A5: Pokemon | B5: Any 151-set card (Charizard ex SIR, Blastoise ex SIR, etc.) | C5: Ongoing 2026-2028 | D5: 151 UPC reprints, mainline set inserts | E5: Wait 6-12 months post-reprint. Alt Arts from Evolving Skies/Lost Origin are safer.
A6: Pokemon | B6: Pokemon Center exclusives that cross into retail | C6: Variable | D6: Secondary retail distribution | E6: Only preorder Pokemon Center direct. If it hits Target, pass.
A7: Magic | B7: Commander staples outside EDHREC Top 50 (e.g., Sol Ring variants) | C7: Every Commander precon | D7: Commander precon reprints | E7: Buy the Commander precon containing the reprint, not the raw card beforehand.
A8: Magic | B8: Format-staple fetchlands (Polluted Delta, Scalding Tarn) | C8: 2026-2028 | D8: Standard/Modern Horizons reprints | E8: Watch MH4 spoilers June 2027. Wait for reprint-driven floor.
A9: Yu-Gi-Oh | B9: Dark Magician / Blue-Eyes / Exodia reprints | C9: Annual (~2 per year) | D9: Legendary Collections, 25th/30th Anniversary products | E9: Only buy pre-2010 1st Edition graded. Modern reprints always coming.
A10: Yu-Gi-Oh | B10: Modern meta staples not yet on banlist | C10: Quarterly | D10: Structure decks + core boosters | E10: Meta staples always reprint. Buy Quarter Century Secret Rares instead.
A11: OnePiece | B11: OP-01 through OP-03 secondary singles (older meta cards) | C11: 2026-2027 | D11: Premium Booster reprint sets | E11: Bandai has reprinted older staples through Premium Boosters. Wait.
A12: Flesh and Blood | B12: Common Legendary equipment reprints | C12: 2026-2027 | D12: Beyond set + History Pack cycles | E12: Cold Foil Legendaries from sold-out sets only. Avoid majestic reprints.
A13: Lorcana | B13: First Chapter common-uncommon cards | C13: Ongoing | D13: Gateway Starter set + retail reprints | E13: Only Enchanted variants hold value. Commons always reprint.
A14: Baseball | B14: Topps flagship base rookies before Chrome/Heritage | C14: Year-round | D14: Multiple Topps products reissue same player base design | E14: Wait for Chrome/Bowman Chrome RC Refractors — not flagship base.

Sheet Buy_Queue
A1: Priority-Ranked Buy Queue
A2: Ranked by priority (1 first, then 2), then by date. Running budget total in column H — stop when budget is exhausted.
A4: # | B4: Priority | C4: Buy Window Start | D4: Category | E4: Product | F4: Action | G4: Budget ($) | H4: Running Total ($)
A5: 1 | B5: 1 — Must buy | C5: 46127 | D5: Magic | E5: Final Fantasy Universes Beyond | F5: Preorder now | G5: 120 | H5: =SUM($G$5:G5) -> 120
A6: 2 | B6: 1 — Must buy | C6: 46127 | D6: Magic | E6: Final Fantasy — Commander Decks | F6: Preorder now | G6: 75 | H6: =SUM($G$5:G6) -> 195
A7: 3 | B7: 1 — Must buy | C7: 46143 | D7: Pokemon | E7: Mega Evolution main set (English, est. Destined Horizons) | F7: Preorder now | G7: 100 | H7: =SUM($G$5:G7) -> 295
A8: 4 | B8: 1 — Must buy | C8: 46143 | D8: Soccer_WC | E8: Panini Prizm World Cup 2026 (Hobby) | F8: Preorder now | G8: 180 | H8: =SUM($G$5:G8) -> 475
A9: 5 | B9: 1 — Must buy | C9: 46218 | D9: Basketball | E9: Topps NBA flagship inaugural release | F9: Preorder now | G9: 180 | H9: =SUM($G$5:G9) -> 655
A10: 6 | B10: 1 — Must buy | C10: 46249 | D10: Pokemon | E10: Pokemon TCG 30th Anniversary Celebration Collection (est.) | F10: Preorder now | G10: 120 | H10: =SUM($G$5:G10) -> 775
A11: 7 | B11: 1 — Must buy | C11: 46266 | D11: Magic | E11: Avatar: The Last Airbender — Commander Decks | F11: Preorder now | G11: 75 | H11: =SUM($G$5:G11) -> 850
A12: 8 | B12: 1 — Must buy | C12: 46300 | D12: Football | E12: Topps NFL flagship inaugural (est.) | F12: Preorder now | G12: 180 | H12: =SUM($G$5:G12) -> 1030
A13: 9 | B13: 1 — Must buy | C13: 46341 | D13: Pokemon | E13: Prismatic Evolutions-successor (est. Eevee-focused) | F13: Preorder now | G13: 165 | H13: =SUM($G$5:G13) -> 1195
